#VRML_SIM R2022a utf8
WorldInfo {
}
Viewpoint {
  orientation 0.5773502691896258 -0.5773502691896258 -0.5773502691896258 4.188785307179587
  position 0.00019843382727003118 -4.552154441923753e-06 5.642782304428511
}
TexturedBackground {
}
TexturedBackgroundLight {
}
RectangleArena {
  rotation 0 1 0 4.692820414042842e-06
  floorSize 3 3
}
DEF fab Robot {
  translation -0.725592 -1.25629 0.0613
  rotation 0 0 1 1.5707996938995747
  scale 0.33 0.33 0.33
  children [
    Group {
      children [
        Shape {
          appearance DEF LIGHT_GRAY PBRAppearance {
            baseColor 0.78 0.78 0.78
            roughness 0.1
            metalness 0.3
          }
          geometry Mesh {
            url [
              "https://raw.githubusercontent.com/cyberbotics/webots/R2022a/projects/robots/rec/fabtino/protos/meshes/base_central.dae"
            ]
          }
        }
        Shape {
          appearance DEF DARK_GRAY PBRAppearance {
            baseColor 0.43 0.43 0.43
            roughness 0.1
            metalness 0.3
          }
          geometry Mesh {
            url [
              "https://raw.githubusercontent.com/cyberbotics/webots/R2022a/projects/robots/rec/fabtino/protos/meshes/base.dae"
            ]
          }
        }
      ]
    }
    DEF HJ_FR HingeJoint {
      jointParameters HingeJointParameters {
        axis 0 1 0
        anchor 0.285061 -0.235818 0.035257
      }
      device [
        RotationalMotor {
          name "front_right_wheel_joint"
          maxVelocity 100
          maxTorque 100
        }
        PositionSensor {
          name "front_right_wheel_joint_sensor"
        }
      ]
      endPoint Solid {
        translation 0.285061 -0.235818 0.035257
        rotation 0 1 0 0
        children [
          DEF WHEEL_FR Group {
            children [
              Shape {
                appearance DEF WHEEL_APPEARANCE PBRAppearance {
                  baseColor 0.49 0.49 0.49
                  roughness 0.3
                  metalness 0.2
                }
                geometry DEF WHEEL_RIGHT Mesh {
                  url [
                    "https://raw.githubusercontent.com/cyberbotics/webots/R2022a/projects/robots/rec/fabtino/protos/meshes/wheel1.dae"
                  ]
                }
              }
              Shape {
                appearance DEF ROLLERS_APPEARANCE PBRAppearance {
                  baseColor 0.24 0.24 0.24
                  roughness 0.9
                  metalness 0
                }
                geometry DEF ROLLERS_RIGHT Mesh {
                  url [
                    "https://raw.githubusercontent.com/cyberbotics/webots/R2022a/projects/robots/rec/fabtino/protos/meshes/rollers1.dae"
                  ]
                }
              }
            ]
          }
        ]
        name "wheel_fr"
        contactMaterial "InteriorWheelMat"
        boundingObject Transform {
          translation 0 -0.0172 0
          rotation 1 0 0 1.5708
          children [
            DEF BO_WHEEL Cylinder {
              height 0.07
              radius 0.1
            }
          ]
        }
        physics DEF PHYSICS_WHEEL Physics {
        }
      }
    }
    DEF HJ_BR HingeJoint {
      jointParameters HingeJointParameters {
        axis 0 1 0
        anchor -0.284897 -0.238057 0.03513
      }
      device [
        RotationalMotor {
          name "back_right_wheel_joint"
          maxVelocity 100
          maxTorque 100
        }
        PositionSensor {
          name "back_right_wheel_joint_sensor"
        }
      ]
      endPoint Solid {
        translation -0.284897 -0.238057 0.03513
        rotation 0 1 0 0
        children [
          DEF WHEEL_BR Group {
            children [
              Shape {
                appearance USE WHEEL_APPEARANCE
                geometry DEF WHEEL_LEFT Mesh {
                  url [
                    "https://raw.githubusercontent.com/cyberbotics/webots/R2022a/projects/robots/rec/fabtino/protos/meshes/wheel2.dae"
                  ]
                }
              }
              Shape {
                appearance USE ROLLERS_APPEARANCE
                geometry DEF ROLLERS_LEFT Mesh {
                  url [
                    "https://raw.githubusercontent.com/cyberbotics/webots/R2022a/projects/robots/rec/fabtino/protos/meshes/rollers2.dae"
                  ]
                }
              }
            ]
          }
        ]
        name "wheel_br"
        contactMaterial "ExteriorWheelMat"
        boundingObject Transform {
          translation 0 -0.015 0
          rotation 1 0 0 1.5708
          children [
            USE BO_WHEEL
          ]
        }
        physics USE PHYSICS_WHEEL
      }
    }
    DEF HJ_FL HingeJoint {
      jointParameters HingeJointParameters {
        axis 0 1 0
        anchor 0.284897 0.238057 0.03513
      }
      device [
        RotationalMotor {
          name "front_left_wheel_joint"
          maxVelocity 100
          maxTorque 100
        }
        PositionSensor {
          name "front_left_wheel_joint_sensor"
        }
      ]
      endPoint Solid {
        translation 0.284897 0.238057 0.03513
        rotation 0 1 0 0
        children [
          DEF WHEEL_FL Transform {
            rotation 0 0 1 3.141592653589793
            children [
              Shape {
                appearance USE ROLLERS_APPEARANCE
                geometry USE ROLLERS_LEFT
              }
              Shape {
                appearance USE WHEEL_APPEARANCE
                geometry USE WHEEL_LEFT
              }
            ]
          }
        ]
        name "wheel_fl"
        contactMaterial "ExteriorWheelMat"
        boundingObject Transform {
          translation 0 0.015 0
          rotation 1 0 0 1.5708
          children [
            USE BO_WHEEL
          ]
        }
        physics USE PHYSICS_WHEEL
      }
    }
    DEF HJ_BL HingeJoint {
      jointParameters HingeJointParameters {
        axis 0 1 0
        anchor -0.285061 0.235818 0.035257
      }
      device [
        RotationalMotor {
          name "back_left_wheel_joint"
          maxVelocity 100
          maxTorque 100
        }
        PositionSensor {
          name "back_left_wheel_joint_sensor"
        }
      ]
      endPoint Solid {
        translation -0.285061 0.235818 0.035257
        rotation 0 1 0 0
        children [
          DEF WHEEL_BL Transform {
            rotation 0 0 1 3.141592653589793
            children [
              Shape {
                appearance USE WHEEL_APPEARANCE
                geometry USE WHEEL_RIGHT
              }
              Shape {
                appearance USE ROLLERS_APPEARANCE
                geometry USE ROLLERS_RIGHT
              }
            ]
          }
        ]
        name "wheel_bl"
        contactMaterial "InteriorWheelMat"
        boundingObject Transform {
          translation 0 0.0172 0
          rotation 1 0 0 1.5708
          children [
            USE BO_WHEEL
          ]
        }
        physics USE PHYSICS_WHEEL
      }
    }
    DEF IMU Transform {
      children [
        Accelerometer {
          lookupTable [
            -100 -100 -0.002
            100 100 0.002
          ]
        }
        Gyro {
          lookupTable [
            -100 -100 -0.002
            100 100 0.002
          ]
        }
        Compass {
          lookupTable [
            -1 -1 -0.2
            1 1 0.2
          ]
        }
      ]
    }
    Transform {
      translation 0 0 0.145
    }
    Transform {
      translation 0.365 0 0.161
    }
    Transform {
      translation -0.365 0 0.161
      rotation 0 0 1 3.14159
    }
  ]
  name "Fabtino"
  boundingObject Group {
    children [
      DEF FRAME_CENTER Transform {
        translation 0 0 -0.0115
        children [
          Box {
            size 0.726 0.63 0.031
          }
        ]
      }
      DEF FRAME_SIDES Transform {
        translation 0 0 -0.0115
        children [
          Box {
            size 0.87 0.486 0.031
          }
        ]
      }
      DEF FRAME_CORNER_FL Transform {
        translation 0.363 0.243 -0.0115
        children [
          DEF FRAME_CORNER_CYLINDER Cylinder {
            height 0.031
            radius 0.072
          }
        ]
      }
      DEF FRAME_CORNER_FR Transform {
        translation -0.363 0.243 -0.0115
        children [
          USE FRAME_CORNER_CYLINDER
        ]
      }
      DEF FRAME_CORNER_BL Transform {
        translation 0.363 -0.243 -0.0115
        children [
          USE FRAME_CORNER_CYLINDER
        ]
      }
      DEF FRAME_CORNER_BR Transform {
        translation -0.363 -0.243 -0.0115
        children [
          USE FRAME_CORNER_CYLINDER
        ]
      }
      Transform {
        translation 0 0 0.062
        children [
          Box {
            size 0.343 0.603 0.167
          }
        ]
      }
      Transform {
        translation 0 0 0.062
        children [
          Box {
            size 0.843 0.423 0.167
          }
        ]
      }
    ]
  }
  physics Physics {
    density -1
    mass 30
  }
  controller "fabtino"
  supervisor TRUE
}
DEF create1 Create {
  translation -0.609522 -0.330213 0.044
  rotation 0 0 1 -3.141592653589793
  name "Create1"
  supervisor TRUE
}
DEF create2 Create {
  translation 0.883184 -0.137149 0.044
  rotation 0 0 1 0.1308996938995747
  name "Create2"
  supervisor TRUE
}
Wall {
  translation -0.0139521 -0.142863 -8.88178e-15
  size 0.05 2.75 0.23
}
